using Application.Common.Exceptions;
using System.ComponentModel.DataAnnotations;

public class ExceptionHandlingMiddleware
{
    private readonly RequestDelegate _next;
    private readonly ILogger<ExceptionHandlingMiddleware> _logger;

    public ExceptionHandlingMiddleware(RequestDelegate next, ILogger<ExceptionHandlingMiddleware> logger)
    {
        _next = next;
        _logger = logger;
    }

    public async Task Invoke(HttpContext context)
    {
        try
        {
            await _next(context);
        }
        catch (NotFoundException ex)
        {
            _logger.LogWarning(ex, "Resource not found.");
            context.Response.StatusCode = StatusCodes.Status404NotFound;
            await context.Response.WriteAsJsonAsync(new { message = ex.Message });
        }
        catch (ValidationException ex)
        {
            _logger.LogWarning(ex, "Erreur de validation.");
            context.Response.StatusCode = StatusCodes.Status400BadRequest;
            await context.Response.WriteAsJsonAsync(new { message = ex.Message });
        }
        catch (DuplicateException ex)
        {
            _logger.LogWarning(ex, "Duplicate.");
            context.Response.StatusCode = StatusCodes.Status400BadRequest;
            await context.Response.WriteAsJsonAsync(new { message = ex.Message });
        }
        catch (Exception ex)
        {
            _logger.LogError(ex, "Erreur interne.");
            context.Response.StatusCode = StatusCodes.Status500InternalServerError;
            await context.Response.WriteAsJsonAsync(new { message = "Une erreur interne est survenue." });
        }
    }
}